Traceback (most recent call last):
  File "/home/smohr/Repositories/dask_performance/benchmarks/mcmc_pi/np/./mcmc_pi.py", line 25, in <module>
    radius = x**2 + y**2
numpy.core._exceptions._ArrayMemoryError: Unable to allocate 74.5 GiB for an array with shape (10000000000,) and data type float64
Traceback (most recent call last):
  File "/home/smohr/Repositories/dask_performance/benchmarks/mcmc_pi/np/./mcmc_pi.py", line 25, in <module>
    Usage:
numpy.core._exceptions._ArrayMemoryError: Unable to allocate 74.5 GiB for an array with shape (10000000000,) and data type float64
Exception in thread Thread-1:
Traceback (most recent call last):
  File "/data.nst/smohr/anaconda3/envs/dask/lib/python3.9/threading.py", line 980, in _bootstrap_inner
Exception in thread Thread-2:
Traceback (most recent call last):
  File "/data.nst/smohr/anaconda3/envs/dask/lib/python3.9/threading.py", line 980, in _bootstrap_inner
Exception in thread Thread-3:
Traceback (most recent call last):
  File "/data.nst/smohr/anaconda3/envs/dask/lib/python3.9/threading.py", line 980, in _bootstrap_inner
Exception in thread Thread-4:
Traceback (most recent call last):
  File "/data.nst/smohr/anaconda3/envs/dask/lib/python3.9/threading.py", line 980, in _bootstrap_inner
Exception in thread Thread-5:
    self.run()
Exception in thread   File "/data.nst/smohr/anaconda3/envs/dask/lib/python3.9/threading.py", line 917, in run
Thread-6Traceback (most recent call last):
  File "/data.nst/smohr/anaconda3/envs/dask/lib/python3.9/threading.py", line 980, in _bootstrap_inner
    Exception in thread Thread-7:
self.run()
  File "/data.nst/smohr/anaconda3/envs/dask/lib/python3.9/threading.py", line 917, in run
:
Traceback (most recent call last):
  File "/data.nst/smohr/anaconda3/envs/dask/lib/python3.9/threading.py", line 980, in _bootstrap_inner
    self._target(*self._args, **self._kwargs)    
TypeError:         self.run()calc_pi_thread() missing 1 required positional argument: 'local_trials'
Traceback (most recent call last):
self.run()
  File "/data.nst/smohr/anaconda3/envs/dask/lib/python3.9/threading.py", line 917, in run
self.run()
  File "/data.nst/smohr/anaconda3/envs/dask/lib/python3.9/threading.py", line 917, in run

  File "/data.nst/smohr/anaconda3/envs/dask/lib/python3.9/threading.py", line 917, in run
        Exception in thread Thread-8:
Traceback (most recent call last):
  File "/data.nst/smohr/anaconda3/envs/dask/lib/python3.9/threading.py", line 980, in _bootstrap_inner
    Exception in thread Thread-9:
    self._target(*self._args, **self._kwargs)
TypeError: Traceback (most recent call last):
  File "/data.nst/smohr/anaconda3/envs/dask/lib/python3.9/threading.py", line 980, in _bootstrap_inner
self._target(*self._args, **self._kwargs)
TypeError: self._target(*self._args, **self._kwargs)
TypeError: calc_pi_thread() missing 1 required positional argument: 'local_trials'
  File "/data.nst/smohr/anaconda3/envs/dask/lib/python3.9/threading.py", line 980, in _bootstrap_inner
    self.run()
  File "/data.nst/smohr/anaconda3/envs/dask/lib/python3.9/threading.py", line 917, in run
Exception in thread Thread-10:
calc_pi_thread() missing 1 required positional argument: 'local_trials'
self.run()
  File "/data.nst/smohr/anaconda3/envs/dask/lib/python3.9/threading.py", line 917, in run
        self.run()
self._target(*self._args, **self._kwargs)
TypeError: calc_pi_thread() missing 1 required positional argument: 'local_trials'
    Exception in thread Thread-11:
  File "/data.nst/smohr/anaconda3/envs/dask/lib/python3.9/threading.py", line 917, in run
calc_pi_thread() missing 1 required positional argument: 'local_trials'
    self._target(*self._args, **self._kwargs)
Traceback (most recent call last):
  File "/data.nst/smohr/anaconda3/envs/dask/lib/python3.9/threading.py", line 980, in _bootstrap_inner
TypeError: calc_pi_thread() missing 1 required positional argument: 'local_trials'
Traceback (most recent call last):
  File "/data.nst/smohr/anaconda3/envs/dask/lib/python3.9/threading.py", line 980, in _bootstrap_inner
self._target(*self._args, **self._kwargs)
Exception in thread TypeError    self.run()
      File "/data.nst/smohr/anaconda3/envs/dask/lib/python3.9/threading.py", line 917, in run
: calc_pi_thread() missing 1 required positional argument: 'local_trials'
self.run()
Thread-12:
Exception in thread Thread-13:
Traceback (most recent call last):
  File "/data.nst/smohr/anaconda3/envs/dask/lib/python3.9/threading.py", line 980, in _bootstrap_inner
        self._target(*self._args, **self._kwargs)
    self.run()
  File "/data.nst/smohr/anaconda3/envs/dask/lib/python3.9/threading.py", line 917, in run
        self._target(*self._args, **self._kwargs)
TypeError: calc_pi_thread() missing 1 required positional argument: 'local_trials'Exception in thread Thread-14:
  File "/data.nst/smohr/anaconda3/envs/dask/lib/python3.9/threading.py", line 917, in run
self._target(*self._args, **self._kwargs)
self.run()
Traceback (most recent call last):
  File "/data.nst/smohr/anaconda3/envs/dask/lib/python3.9/threading.py", line 980, in _bootstrap_inner
TypeError: calc_pi_thread() missing 1 required positional argument: 'local_trials'Traceback (most recent call last):
  File "/data.nst/smohr/anaconda3/envs/dask/lib/python3.9/threading.py", line 980, in _bootstrap_inner
  File "/data.nst/smohr/anaconda3/envs/dask/lib/python3.9/threading.py", line 917, in run

TypeError: calc_pi_thread() missing 1 required positional argument: 'local_trials'
Exception in thread 
    self._target(*self._args, **self._kwargs)
Thread-15:
Exception in thread Thread-16:
TypeError:     self.run()
Traceback (most recent call last):
  File "/data.nst/smohr/anaconda3/envs/dask/lib/python3.9/threading.py", line 980, in _bootstrap_inner
Traceback (most recent call last):
  File "/data.nst/smohr/anaconda3/envs/dask/lib/python3.9/threading.py", line 980, in _bootstrap_inner
calc_pi_thread() missing 1 required positional argument: 'local_trials'
    Exception in thread     Thread-17    self.run()
self.run()
  File "/data.nst/smohr/anaconda3/envs/dask/lib/python3.9/threading.py", line 917, in run
self._target(*self._args, **self._kwargs)
TypeError: calc_pi_thread() missing 1 required positional argument: 'local_trials'Exception in thread   File "/data.nst/smohr/anaconda3/envs/dask/lib/python3.9/threading.py", line 917, in run

  File "/data.nst/smohr/anaconda3/envs/dask/lib/python3.9/threading.py", line 917, in run
Thread-18:
Traceback (most recent call last):
  File "/data.nst/smohr/anaconda3/envs/dask/lib/python3.9/threading.py", line 980, in _bootstrap_inner
    self.run()
    :
Traceback (most recent call last):
  File "/data.nst/smohr/anaconda3/envs/dask/lib/python3.9/threading.py", line 980, in _bootstrap_inner
    Exception in thread Thread-19:
self.run()
  File "/data.nst/smohr/anaconda3/envs/dask/lib/python3.9/threading.py", line 917, in run
  File "/data.nst/smohr/anaconda3/envs/dask/lib/python3.9/threading.py", line 917, in run
self._target(*self._args, **self._kwargs)
Traceback (most recent call last):
  File "/data.nst/smohr/anaconda3/envs/dask/lib/python3.9/threading.py", line 980, in _bootstrap_inner
    self._target(*self._args, **self._kwargs)
TypeError: TypeError: calc_pi_thread() missing 1 required positional argument: 'local_trials'
    self.run()
Exception in thread Thread-20:
    self.run()
  File "/data.nst/smohr/anaconda3/envs/dask/lib/python3.9/threading.py", line 917, in run
  File "/data.nst/smohr/anaconda3/envs/dask/lib/python3.9/threading.py", line 917, in run
Traceback (most recent call last):
  File "/data.nst/smohr/anaconda3/envs/dask/lib/python3.9/threading.py", line 980, in _bootstrap_inner
Exception in thread Thread-21:
        calc_pi_thread() missing 1 required positional argument: 'local_trials'
self._target(*self._args, **self._kwargs)
TypeError: calc_pi_thread() missing 1 required positional argument: 'local_trials'    self._target(*self._args, **self._kwargs)Exception in thread Thread-22:
Traceback (most recent call last):


TypeError: calc_pi_thread() missing 1 required positional argument: 'local_trials'Traceback (most recent call last):
  File "/data.nst/smohr/anaconda3/envs/dask/lib/python3.9/threading.py", line 980, in _bootstrap_inner
self._target(*self._args, **self._kwargs)
TypeError    self.run(): calc_pi_thread() missing 1 required positional argument: 'local_trials'
    
  File "/data.nst/smohr/anaconda3/envs/dask/lib/python3.9/threading.py", line 917, in run

  File "/data.nst/smohr/anaconda3/envs/dask/lib/python3.9/threading.py", line 980, in _bootstrap_inner
self._target(*self._args, **self._kwargs)
TypeError: Exception in thread calc_pi_thread() missing 1 required positional argument: 'local_trials'Thread-23:
Traceback (most recent call last):

        self.run()
  File "/data.nst/smohr/anaconda3/envs/dask/lib/python3.9/threading.py", line 917, in run
Exception in thread self._target(*self._args, **self._kwargs)
      File "/data.nst/smohr/anaconda3/envs/dask/lib/python3.9/threading.py", line 980, in _bootstrap_inner
    self._target(*self._args, **self._kwargs)
Thread-24:
Traceback (most recent call last):
  File "/data.nst/smohr/anaconda3/envs/dask/lib/python3.9/threading.py", line 980, in _bootstrap_inner
TypeError: calc_pi_thread() missing 1 required positional argument: 'local_trials'
TypeError: calc_pi_thread() missing 1 required positional argument: 'local_trials'self.run()Exception in thread Thread-25:

      File "/data.nst/smohr/anaconda3/envs/dask/lib/python3.9/threading.py", line 917, in run

self._target(*self._args, **self._kwargs)
    self.run()
Traceback (most recent call last):
  File "/data.nst/smohr/anaconda3/envs/dask/lib/python3.9/threading.py", line 980, in _bootstrap_inner
Exception in thread   File "/data.nst/smohr/anaconda3/envs/dask/lib/python3.9/threading.py", line 917, in run
    Thread-26    self._target(*self._args, **self._kwargs)
    self.run()
  File "/data.nst/smohr/anaconda3/envs/dask/lib/python3.9/threading.py", line 917, in run
:
Traceback (most recent call last):
  File "/data.nst/smohr/anaconda3/envs/dask/lib/python3.9/threading.py", line 980, in _bootstrap_inner
Exception in thread Thread-27:
self.run()
  File "/data.nst/smohr/anaconda3/envs/dask/lib/python3.9/threading.py", line 917, in run
        self.run()
  File "/data.nst/smohr/anaconda3/envs/dask/lib/python3.9/threading.py", line 917, in run
self._target(*self._args, **self._kwargs)    self._target(*self._args, **self._kwargs)
TypeError: calc_pi_thread() missing 1 required positional argument: 'local_trials'
TypeErrorTraceback (most recent call last):
  File "/data.nst/smohr/anaconda3/envs/dask/lib/python3.9/threading.py", line 980, in _bootstrap_inner

TypeError: calc_pi_thread() missing 1 required positional argument: 'local_trials'TypeErrorException in thread Thread-28:
: calc_pi_thread() missing 1 required positional argument: 'local_trials'
Exception in thread Thread-29:
Exception in thread Thread-30:
Traceback (most recent call last):
  File "/data.nst/smohr/anaconda3/envs/dask/lib/python3.9/threading.py", line 980, in _bootstrap_inner
: calc_pi_thread() missing 1 required positional argument: 'local_trials'
Traceback (most recent call last):
  File "/data.nst/smohr/anaconda3/envs/dask/lib/python3.9/threading.py", line 980, in _bootstrap_inner
    self._target(*self._args, **self._kwargs)Traceback (most recent call last):
  File "/data.nst/smohr/anaconda3/envs/dask/lib/python3.9/threading.py", line 980, in _bootstrap_inner


TypeError: Exception in thread     self._target(*self._args, **self._kwargs)
TypeError: calc_pi_thread() missing 1 required positional argument: 'local_trials'    self.run()
calc_pi_thread() missing 1 required positional argument: 'local_trials'
Thread-31:
Traceback (most recent call last):
  File "/data.nst/smohr/anaconda3/envs/dask/lib/python3.9/threading.py", line 980, in _bootstrap_inner
Exception in thread Thread-32:
    self.run()
  File "/data.nst/smohr/anaconda3/envs/dask/lib/python3.9/threading.py", line 917, in run
    self.run()

    self.run()  File "/data.nst/smohr/anaconda3/envs/dask/lib/python3.9/threading.py", line 917, in run
Traceback (most recent call last):
  File "/data.nst/smohr/anaconda3/envs/dask/lib/python3.9/threading.py", line 980, in _bootstrap_inner

      File "/data.nst/smohr/anaconda3/envs/dask/lib/python3.9/threading.py", line 917, in run
  File "/data.nst/smohr/anaconda3/envs/dask/lib/python3.9/threading.py", line 917, in run
self.run()
  File "/data.nst/smohr/anaconda3/envs/dask/lib/python3.9/threading.py", line 917, in run
            self._target(*self._args, **self._kwargs)
self._target(*self._args, **self._kwargs)    
TypeError:     calc_pi_thread() missing 1 required positional argument: 'local_trials'
    TypeError: calc_pi_thread() missing 1 required positional argument: 'local_trials'
self.run()
  File "/data.nst/smohr/anaconda3/envs/dask/lib/python3.9/threading.py", line 917, in run
self._target(*self._args, **self._kwargs)
TypeError: self._target(*self._args, **self._kwargs)
TypeError: calc_pi_thread() missing 1 required positional argument: 'local_trials'self._target(*self._args, **self._kwargs)
TypeError: calc_pi_thread() missing 1 required positional argument: 'local_trials'
calc_pi_thread() missing 1 required positional argument: 'local_trials'

    self._target(*self._args, **self._kwargs)
TypeError: calc_pi_thread() missing 1 required positional argument: 'local_trials'
Traceback (most recent call last):
  File "/home/smohr/Repositories/dask_performance/benchmarks/mcmc_pi/np/./mcmc_pi.py", line 49, in <module>
    pi = mean(results)
  File "/home/smohr/Repositories/dask_performance/benchmarks/mcmc_pi/np/./mcmc_pi.py", line 12, in mean
    return sum(runs)/len(runs)
TypeError: unsupported operand type(s) for +: 'int' and 'NoneType'
Traceback (most recent call last):
  File "/home/smohr/Repositories/dask_performance/benchmarks/mcmc_pi/np/./mcmc_pi.py", line 25, in <module>
    Usage:
numpy.core._exceptions._ArrayMemoryError: Unable to allocate 74.5 GiB for an array with shape (10000000000,) and data type float64
/core/UGE2011.11p1/LMP/spool/sam127/job_scripts/7143862: line 21: 110181 Killed                  python -u ./mcmc_pi.py 100000000000 $SGE_TASK_ID >> ../data/times_numpy_trials-100000000000_parallel-32.txt
